Workbook

Sheet Léeme
B2: Sky Apex · Stats de las unidades
B3: El juego lee todas las stats de este Excel: los dragones del jugador, los enemigos y Lance. Cambia un valor, guarda (Ctrl+G) y el juego lo usa.
B4: Qué se puede cambiar
B5: • Solo la columna «Valor» (en amarillo) de cada pestaña.
B6: • Base: los valores base de todos los dragones del jugador.
B7: • Alientormenta, Abrasanubes, Ventoscuro y Fulgor: su «Valor» copia el de la Base (es una fórmula) hasta que escribas otro número; esa es su variación.
B8: «Diferencia» dice cuánto se aparta de la Base, y el valor se pone en naranja. Para volver a la Base, escribe en la celda: =Base!B<fila> (o copia la de otra fila).
B9: • Comparativa: los cuatro dragones y la Base lado a lado (solo para mirar; se rellena sola). En naranja, lo que cambia respecto a la Base.
B10: • Dragón enemigo, Torre, Dirigible y Lance (aliado): sus valores de ahora, pendientes de rediseñar.
B11: • Artillería, Batallón, Barco naval, Superdirigible y Sierpe (v29): los enemigos nuevos, con valores provisionales para ajustarlos en la galería de enemigos.
B12: • En gris: ajustes que no estaban en la lista de stats; tienen los valores que ya usaba el juego.
B13: Qué no hay que cambiar
... B22: Velocidades de dragones en km/h; de proyectiles, en m/s. Distancias en m (el rayo, en km). Tiempos en s. Recargas en % de la barra por segundo.

Sheet Comparativa
A1: Comparativa de los dragones
A2: Solo para mirar: se rellena sola con las pestañas de cada dragón. En naranja, lo que cambia respecto a la Base.
A4: Stat | B4: Unidad | C4: Base | D4: Alientormenta | E4: Abrasanubes | F4: Ventoscuro | G4: Fulgor
A5: Vida y defensa
A6: Puntos de vida | B6: puntos | C6: =Base!B6 -> 100 | D6: ='Alientormenta'!B6 -> 100 | E6: ='Abrasanubes'!B6 -> 100 | F6: ='Ventoscuro'!B6 -> 100 | G6: ='Fulgor'!B6 -> 100
A7: Puntos de armadura | B7: puntos | C7: =Base!B7 -> 50 | D7: ='Alientormenta'!B7 -> 50 | E7: ='Abrasanubes'!B7 -> 50 | F7: ='Ventoscuro'!B7 -> 50 | G7: ='Fulgor'!B7 -> 50
A8: Espera para regenerar la armadura | B8: s | C8: =Base!B8 -> 5 | D8: ='Alientormenta'!B8 -> 5 | E8: ='Abrasanubes'!B8 -> 5 | F8: ='Ventoscuro'!B8 -> 5 | G8: ='Fulgor'!B8 -> 5
A9: Regeneración de armadura | B9: puntos/s | C9: =Base!B9 -> 5 | D9: ='Alientormenta'!B9 -> 5 | E9: ='Abrasanubes'!B9 -> 5 | F9: ='Ventoscuro'!B9 -> 5 | G9: ='Fulgor'!B9 -> 5
A10: Slots de escudo | B10: cargas | C10: =Base!B10 -> 2 | D10: ='Alientormenta'!B10 -> 2 | E10: ='Abrasanubes'!B10 -> 2 | F10: ='Ventoscuro'!B10 -> 2 | G10: ='Fulgor'!B10 -> 2
A11: Duración del escudo | B11: s | C11: =Base!B11 -> 5 | D11: ='Alientormenta'!B11 -> 5 | E11: ='Abrasanubes'!B11 -> 5 | F11: ='Ventoscuro'!B11 -> 5 | G11: ='Fulgor'!B11 -> 5
A12: Escudo por dragón derribado | B12: cargas | C12: =Base!B12 -> 1 | D12: ='Alientormenta'!B12 -> 1 | E12: ='Abrasanubes'!B12 -> 1 | F12: ='Ventoscuro'!B12 -> 1 | G12: ='Fulgor'!B12 -> 1
A13: Disparo básico (clic izquierdo)
A14: Daño disparo básico | B14: puntos | C14: =Base!B14 -> 5 | D14: ='Alientormenta'!B14 -> 5 | E14: ='Abrasanubes'!B14 -> 5 | F14: ='Ventoscuro'!B14 -> 5 | G14: ='Fulgor'!B14 -> 5
A15: Munición disparo básico | B15: disparos | C15: =Base!B15 -> 20 | D15: ='Alientormenta'!B15 -> 20 | E15: ='Abrasanubes'!B15 -> 20 | F15: ='Ventoscuro'!B15 -> 20 | G15: ='Fulgor'!B15 -> 20
A16: Pausa mínima entre disparos | B16: s | C16: =Base!B16 -> 0.1 | D16: ='Alientormenta'!B16 -> 0.1 | E16: ='Abrasanubes'!B16 -> 0.1 | F16: ='Ventoscuro'!B16 -> 0.1 | G16: ='Fulgor'!B16 -> 0.1
A17: Espera antes de recargar | B17: s | C17: =Base!B17 -> 1 | D17: ='Alientormenta'!B17 -> 1 | E17: ='Abrasanubes'!B17 -> 1 | F17: ='Ventoscuro'!B17 -> 1 | G17: ='Fulgor'!B17 -> 1
A18: Recarga de munición | B18: disparos/s | C18: =Base!B18 -> 8 | D18: ='Alientormenta'!B18 -> 8 | E18: ='Abrasanubes'!B18 -> 8 | F18: ='Ventoscuro'!B18 -> 8 | G18: ='Fulgor'!B18 -> 8
A19: Disparo guiado (clic izquierdo mantenido)
A20: Daño disparo guiado | B20: puntos | C20: =Base!B20 -> 60 | D20: ='Alientormenta'!B20 -> 60 | E20: ='Abrasanubes'!B20 -> 60 | F20: ='Ventoscuro'!B20 -> 60 | G20: ='Fulgor'!B20 -> 60
A21: Munición disparo guiado | B21: disparos | C21: =Base!B21 -> 20 | D21: ='Alientormenta'!B21 -> 20 | E21: ='Abrasanubes'!B21 -> 20 | F21: ='Ventoscuro'!B21 -> 20 | G21: ='Fulgor'!B21 -> 20
A22: Alcance del fijado | B22: m | C22: =Base!B22 -> 3000 | D22: ='Alientormenta'!B22 -> 3000 | E22: ='Abrasanubes'!B22 -> 3000 | F22: ='Ventoscuro'!B22 -> 3000 | G22: ='Fulgor'!B22 -> 3000
A23: Tiempo de fijado | B23: s | C23: =Base!B23 -> 2 | D23: ='Alientormenta'!B23 -> 2 | E23: ='Abrasanubes'!B23 -> 2 | F23: ='Ventoscuro'!B23 -> 2 | G23: ='Fulgor'!B23 -> 2
A24: Lanzallamas (clic derecho)
A25: Daño lanzallamas | B25: puntos/s | C25: =Base!B25 -> 15 | D25: ='Alientormenta'!B25 -> 15 | E25: ='Abrasanubes'!B25 -> 15 | F25: ='Ventoscuro'!B25 -> 15 | G25: ='Fulgor'!B25 -> 15
A26: Alcance lanzallamas | B26: m | C26: =Base!B26 -> 300 | D26: ='Alientormenta'!B26 -> 300 | E26: ='Abrasanubes'!B26 -> 300 | F26: ='Ventoscuro'!B26 -> 300 | G26: ='Fulgor'!B26 -> 300
A27: Tiempo sobrecarga del lanzallamas | B27: s | C27: =Base!B27 -> 5 | D27: ='Alientormenta'!B27 -> 5 | E27: ='Abrasanubes'!B27 -> 5 | F27: ='Ventoscuro'!B27 -> 5 | G27: ='Fulgor'!B27 -> 5
A28: Tiempo sin armas al sobrecalentarse | B28: s | C28: =Base!B28 -> 10 | D28: ='Alientormenta'!B28 -> 10 | E28: ='Abrasanubes'!B28 -> 10 | F28: ='Ventoscuro'!B28 -> 10 | G28: ='Fulgor'!B28 -> 10
A29: Tiempo en enfriarse | B29: s | C29: =Base!B29 -> 4 | D29: ='Alientormenta'!B29 -> 4 | E29: ='Abrasanubes'!B29 -> 4 | F29: ='Ventoscuro'!B29 -> 4 | G29: ='Fulgor'!B29 -> 4
A30: Rayo láser (los dos clics a la vez)
A31: Daño rayo láser | B31: puntos/s | C31: =Base!B31 -> 50 | D31: ='Alientormenta'!B31 -> 50 | E31: ='Abrasanubes'!B31 -> 50 | F31: ='Ventoscuro'!B31 -> 50 | G31: ='Fulgor'!B31 -> 50
A32: Duración rayo láser | B32: s | C32: =Base!B32 -> 5 | D32: ='Alientormenta'!B32 -> 5 | E32: ='Abrasanubes'!B32 -> 5 | F32: ='Ventoscuro'!B32 -> 5 | G32: ='Fulgor'!B32 -> 5
A33: Distancia rayo láser | B33: km | C33: =Base!B33 -> 8 | D33: ='Alientormenta'!B33 -> 8 | E33: ='Abrasanubes'!B33 -> 8 | F33: ='Ventoscuro'!B33 -> 8 | G33: ='Fulgor'!B33 -> 8
A34: Recarga rayo láser | B34: %/s | C34: =Base!B34 -> 0.5 | D34: ='Alientormenta'!B34 -> 0.5 | E34: ='Abrasanubes'!B34 -> 0.5 | F34: ='Ventoscuro'!B34 -> 0.5 | G34: ='Fulgor'!B34 -> 0.5
A35: Recarga por enemigo destruido | B35: % | C35: =Base!B35 -> 5 | D35: ='Alientormenta'!B35 -> 5 | E35: ='Abrasanubes'!B35 -> 5 | F35: ='Ventoscuro'!B35 -> 5 | G35: ='Fulgor'!B35 -> 5
A36: Vuelo
A37: Velocidad máxima | B37: km/h | C37: =Base!B37 -> 600 | D37: ='Alientormenta'!B37 -> 600 | E37: ='Abrasanubes'!B37 -> 600 | F37: ='Ventoscuro'!B37 -> 600 | G37: ='Fulgor'!B37 -> 600
A38: Velocidad boost | B38: km/h | C38: =Base!B38 -> 1000 | D38: ='Alientormenta'!B38 -> 1000 | E38: ='Abrasanubes'!B38 -> 1000 | F38: ='Ventoscuro'!B38 -> 1000 | G38: ='Fulgor'!B38 -> 1000
A39: Duración boost | B39: s | C39: =Base!B39 -> 10 | D39: ='Alientormenta'!B39 -> 10 | E39: ='Abrasanubes'!B39 -> 10 | F39: ='Ventoscuro'!B39 -> 10 | G39: ='Fulgor'!B39 -> 10
A40: Aceleración del boost | B40: s | C40: =Base!B40 -> 3 | D40: ='Alientormenta'!B40 -> 3 | E40: ='Abrasanubes'!B40 -> 3 | F40: ='Ventoscuro'!B40 -> 3 | G40: ='Fulgor'!B40 -> 3
A41: Espera para recargar el boost | B41: s | C41: =Base!B41 -> 2 | D41: ='Alientormenta'!B41 -> 2 | E41: ='Abrasanubes'!B41 -> 2 | F41: ='Ventoscuro'!B41 -> 2 | G41: ='Fulgor'!B41 -> 2
...

Sheet Base
A1: Base
A2: Valores base de los dragones del jugador. Cada dragón los copia salvo los que cambies en su pestaña.
A4: Stat | B4: Valor | C4: Unidad | D4: Descripción | E4: Clave
A5: Vida y defensa
A6: Puntos de vida | B6: 100 | C6: puntos | D6: Vida máxima. Ya no se regenera: lo que pierdes no vuelve hasta la siguiente misión (o al reaparecer en el combate libre). | E6: vida
A7: Puntos de armadura | B7: 50 | C7: puntos | D7: Barra amarilla encima de la de vida. El daño la gasta primero a ella y, cuando llega a 0, a la vida. | E7: armadura
A8: Espera para regenerar la armadura | B8: 5 | C8: s | D8: Segundos sin recibir daño antes de que la armadura empiece a rellenarse. | E8: armadura_espera
A9: Regeneración de armadura | B9: 5 | C9: puntos/s | D9: Lo que se rellena cada segundo, hasta el máximo. | E9: armadura_regen
A10: Slots de escudo | B10: 2 | C10: cargas | D10: Cargas del escudo (R) al empezar; también es el máximo. | E10: escudos
A11: Duración del escudo | B11: 5 | C11: s | D11: Segundos que dura cada carga. | E11: escudo_duracion
A12: Escudo por dragón derribado | B12: 1 | C12: cargas | D12: Cargas que devuelve cada dragón que derribas tú (0 = no se recargan). | E12: escudo_por_derribo
A13: Disparo básico (clic izquierdo)
A14: Daño disparo básico | B14: 5 | C14: puntos | D14: Daño de cada impacto. | E14: basico_dano
A15: Munición disparo básico | B15: 20 | C15: disparos | D15: Disparos seguidos; se recargan solos. | E15: basico_municion
A16: Pausa mínima entre disparos | B16: 0.1 | C16: s | D16: Un disparo por clic, como mucho uno cada tanto. | E16: basico_pausa
A17: Espera antes de recargar | B17: 1 | C17: s | D17: Segundos sin disparar antes de que vuelva la munición. | E17: basico_recarga_espera
A18: Recarga de munición | B18: 8 | C18: disparos/s | D18: Disparos que vuelven cada segundo. | E18: basico_recarga
A19: Disparo guiado (clic izquierdo mantenido)
A20: Daño disparo guiado | B20: 60 | C20: puntos | D20: Daño del impacto. | E20: guiado_dano
A21: Munición disparo guiado | B21: 20 | C21: disparos | D21: Cantidad fija por misión: no se recargan. A 0, no hay más. | E21: guiado_municion
A22: Alcance del fijado | B22: 3000 | C22: m | D22: Distancia máxima al blanco para cargar el guiado. | E22: guiado_alcance
A23: Tiempo de fijado | B23: 2 | C23: s | D23: Segundos con la mira en el círculo rojo hasta que sale (v31: 2, antes 3). | E23: guiado_fijado
A24: Lanzallamas (clic derecho)
A25: Daño lanzallamas | B25: 15 | C25: puntos/s | D25: Daño por segundo a todo lo que toca. | E25: llamas_dano
A26: Alcance lanzallamas | B26: 300 | C26: m | D26: Largo del chorro. | E26: llamas_alcance
A27: Tiempo sobrecarga del lanzallamas | B27: 5 | C27: s | D27: Segundos de fuego seguido hasta sobrecalentarse. | E27: llamas_sobrecarga
A28: Tiempo sin armas al sobrecalentarse | B28: 10 | C28: s | D28: Al sobrecalentarse, ninguna arma funciona durante este tiempo. | E28: llamas_bloqueo
A29: Tiempo en enfriarse | B29: 4 | C29: s | D29: Al soltar antes de sobrecalentarse, el calor baja de 100 % a 0 en este tiempo. | E29: llamas_enfriado
A30: Rayo láser (los dos clics a la vez)
A31: Daño rayo láser | B31: 50 | C31: puntos/s | D31: Daño por segundo a todo lo que cruza. | E31: rayo_dano
A32: Duración rayo láser | B32: 5 | C32: s | D32: Segundos desde que lo lanzas. | E32: rayo_duracion
A33: Distancia rayo láser | B33: 8 | C33: km | D33: Largo máximo del rayo (se corta al chocar con el terreno o una isla). | E33: rayo_alcance
A34: Recarga rayo láser | B34: 0.5 | C34: %/s | D34: Carga con el tiempo (con 0,5 %/s, de 0 a 100 % en 200 s). | E34: rayo_recarga
A35: Recarga por enemigo destruido | B35: 5 | C35: % | D35: Por cada dragón, torre, dirigible u otra unidad enemiga que destruyes tú (no Lance; los soldados sueltos no cuentan, el batallón entero sí). | E35: rayo_por_derribo
A36: Vuelo
A37: Velocidad máxima | B37: 600 | C37: km/h | D37: A todo gas y en vuelo nivelado, sin boost (en picado se puede pasar). | E37: vel_max
A38: Velocidad boost | B38: 1000 | C38: km/h | D38: Con boost. También es el tope absoluto, picados incluidos. | E38: vel_boost
A39: Duración boost | B39: 10 | C39: s | D39: Segundos de boost seguido con la barra llena. | E39: boost_duracion
A40: Aceleración del boost | B40: 3 | C40: s | D40: Segundos en pasar de la velocidad máxima a la de boost. | E40: boost_aceleracion
A41: Espera para recargar el boost | B41: 2 | C41: s | D41: Segundos sin usarlo antes de que empiece a recargarse. | E41: boost_espera
...

Sheet Alientormenta
A1: Alientormenta
A2: Dragón del jugador. «Valor» sigue a la Base hasta que escribas otro número (su variación, en naranja).
A4: Stat | B4: Valor | C4: Unidad | D4: Base | E4: Diferencia | F4: Descripción | G4: Clave
A5: Vida y defensa
A6: Puntos de vida | B6: =Base!B6 -> 100 | C6: puntos | D6: =Base!B6 -> 100 | E6: =IF(D6=0,"",B6/D6-1) -> 0 | F6: Vida máxima. Ya no se regenera: lo que pierdes no vuelve hasta la siguiente misión (o al reaparecer en el combate libre). | G6: vida
A7: Puntos de armadura | B7: =Base!B7 -> 50 | C7: puntos | D7: =Base!B7 -> 50 | E7: =IF(D7=0,"",B7/D7-1) -> 0 | F7: Barra amarilla encima de la de vida. El daño la gasta primero a ella y, cuando llega a 0, a la vida. | G7: armadura
A8: Espera para regenerar la armadura | B8: =Base!B8 -> 5 | C8: s | D8: =Base!B8 -> 5 | E8: =IF(D8=0,"",B8/D8-1) -> 0 | F8: Segundos sin recibir daño antes de que la armadura empiece a rellenarse. | G8: armadura_espera
A9: Regeneración de armadura | B9: =Base!B9 -> 5 | C9: puntos/s | D9: =Base!B9 -> 5 | E9: =IF(D9=0,"",B9/D9-1) -> 0 | F9: Lo que se rellena cada segundo, hasta el máximo. | G9: armadura_regen
A10: Slots de escudo | B10: =Base!B10 -> 2 | C10: cargas | D10: =Base!B10 -> 2 | E10: =IF(D10=0,"",B10/D10-1) -> 0 | F10: Cargas del escudo (R) al empezar; también es el máximo. | G10: escudos
A11: Duración del escudo | B11: =Base!B11 -> 5 | C11: s | D11: =Base!B11 -> 5 | E11: =IF(D11=0,"",B11/D11-1) -> 0 | F11: Segundos que dura cada carga. | G11: escudo_duracion
A12: Escudo por dragón derribado | B12: =Base!B12 -> 1 | C12: cargas | D12: =Base!B12 -> 1 | E12: =IF(D12=0,"",B12/D12-1) -> 0 | F12: Cargas que devuelve cada dragón que derribas tú (0 = no se recargan). | G12: escudo_por_derribo
A13: Disparo básico (clic izquierdo)
A14: Daño disparo básico | B14: =Base!B14 -> 5 | C14: puntos | D14: =Base!B14 -> 5 | E14: =IF(D14=0,"",B14/D14-1) -> 0 | F14: Daño de cada impacto. | G14: basico_dano
A15: Munición disparo básico | B15: =Base!B15 -> 20 | C15: disparos | D15: =Base!B15 -> 20 | E15: =IF(D15=0,"",B15/D15-1) -> 0 | F15: Disparos seguidos; se recargan solos. | G15: basico_municion
A16: Pausa mínima entre disparos | B16: =Base!B16 -> 0.1 | C16: s | D16: =Base!B16 -> 0.1 | E16: =IF(D16=0,"",B16/D16-1) -> 0 | F16: Un disparo por clic, como mucho uno cada tanto. | G16: basico_pausa
A17: Espera antes de recargar | B17: =Base!B17 -> 1 | C17: s | D17: =Base!B17 -> 1 | E17: =IF(D17=0,"",B17/D17-1) -> 0 | F17: Segundos sin disparar antes de que vuelva la munición. | G17: basico_recarga_espera
A18: Recarga de munición | B18: =Base!B18 -> 8 | C18: disparos/s | D18: =Base!B18 -> 8 | E18: =IF(D18=0,"",B18/D18-1) -> 0 | F18: Disparos que vuelven cada segundo. | G18: basico_recarga
A19: Disparo guiado (clic izquierdo mantenido)
A20: Daño disparo guiado | B20: =Base!B20 -> 60 | C20: puntos | D20: =Base!B20 -> 60 | E20: =IF(D20=0,"",B20/D20-1) -> 0 | F20: Daño del impacto. | G20: guiado_dano
A21: Munición disparo guiado | B21: =Base!B21 -> 20 | C21: disparos | D21: =Base!B21 -> 20 | E21: =IF(D21=0,"",B21/D21-1) -> 0 | F21: Cantidad fija por misión: no se recargan. A 0, no hay más. | G21: guiado_municion
A22: Alcance del fijado | B22: =Base!B22 -> 3000 | C22: m | D22: =Base!B22 -> 3000 | E22: =IF(D22=0,"",B22/D22-1) -> 0 | F22: Distancia máxima al blanco para cargar el guiado. | G22: guiado_alcance
A23: Tiempo de fijado | B23: =Base!B23 -> 2 | C23: s | D23: =Base!B23 -> 2 | E23: =IF(D23=0,"",B23/D23-1) -> 0 | F23: Segundos con la mira en el círculo rojo hasta que sale (v31: 2, antes 3). | G23: guiado_fijado
A24: Lanzallamas (clic derecho)
A25: Daño lanzallamas | B25: =Base!B25 -> 15 | C25: puntos/s | D25: =Base!B25 -> 15 | E25: =IF(D25=0,"",B25/D25-1) -> 0 | F25: Daño por segundo a todo lo que toca. | G25: llamas_dano
A26: Alcance lanzallamas | B26: =Base!B26 -> 300 | C26: m | D26: =Base!B26 -> 300 | E26: =IF(D26=0,"",B26/D26-1) -> 0 | F26: Largo del chorro. | G26: llamas_alcance
A27: Tiempo sobrecarga del lanzallamas | B27: =Base!B27 -> 5 | C27: s | D27: =Base!B27 -> 5 | E27: =IF(D27=0,"",B27/D27-1) -> 0 | F27: Segundos de fuego seguido hasta sobrecalentarse. | G27: llamas_sobrecarga
A28: Tiempo sin armas al sobrecalentarse | B28: =Base!B28 -> 10 | C28: s | D28: =Base!B28 -> 10 | E28: =IF(D28=0,"",B28/D28-1) -> 0 | F28: Al sobrecalentarse, ninguna arma funciona durante este tiempo. | G28: llamas_bloqueo
A29: Tiempo en enfriarse | B29: =Base!B29 -> 4 | C29: s | D29: =Base!B29 -> 4 | E29: =IF(D29=0,"",B29/D29-1) -> 0 | F29: Al soltar antes de sobrecalentarse, el calor baja de 100 % a 0 en este tiempo. | G29: llamas_enfriado
A30: Rayo láser (los dos clics a la vez)
A31: Daño rayo láser | B31: =Base!B31 -> 50 | C31: puntos/s | D31: =Base!B31 -> 50 | E31: =IF(D31=0,"",B31/D31-1) -> 0 | F31: Daño por segundo a todo lo que cruza. | G31: rayo_dano
A32: Duración rayo láser | B32: =Base!B32 -> 5 | C32: s | D32: =Base!B32 -> 5 | E32: =IF(D32=0,"",B32/D32-1) -> 0 | F32: Segundos desde que lo lanzas. | G32: rayo_duracion
A33: Distancia rayo láser | B33: =Base!B33 -> 8 | C33: km | D33: =Base!B33 -> 8 | E33: =IF(D33=0,"",B33/D33-1) -> 0 | F33: Largo máximo del rayo (se corta al chocar con el terreno o una isla). | G33: rayo_alcance
A34: Recarga rayo láser | B34: =Base!B34 -> 0.5 | C34: %/s | D34: =Base!B34 -> 0.5 | E34: =IF(D34=0,"",B34/D34-1) -> 0 | F34: Carga con el tiempo (con 0,5 %/s, de 0 a 100 % en 200 s). | G34: rayo_recarga
A35: Recarga por enemigo destruido | B35: =Base!B35 -> 5 | C35: % | D35: =Base!B35 -> 5 | E35: =IF(D35=0,"",B35/D35-1) -> 0 | F35: Por cada dragón, torre, dirigible u otra unidad enemiga que destruyes tú (no Lance; los soldados sueltos no cuentan, el batallón entero sí). | G35: rayo_por_derribo
A36: Vuelo
A37: Velocidad máxima | B37: =Base!B37 -> 600 | C37: km/h | D37: =Base!B37 -> 600 | E37: =IF(D37=0,"",B37/D37-1) -> 0 | F37: A todo gas y en vuelo nivelado, sin boost (en picado se puede pasar). | G37: vel_max
A38: Velocidad boost | B38: =Base!B38 -> 1000 | C38: km/h | D38: =Base!B38 -> 1000 | E38: =IF(D38=0,"",B38/D38-1) -> 0 | F38: Con boost. También es el tope absoluto, picados incluidos. | G38: vel_boost
A39: Duración boost | B39: =Base!B39 -> 10 | C39: s | D39: =Base!B39 -> 10 | E39: =IF(D39=0,"",B39/D39-1) -> 0 | F39: Segundos de boost seguido con la barra llena. | G39: boost_duracion
A40: Aceleración del boost | B40: =Base!B40 -> 3 | C40: s | D40: =Base!B40 -> 3 | E40: =IF(D40=0,"",B40/D40-1) -> 0 | F40: Segundos en pasar de la velocidad máxima a la de boost. | G40: boost_aceleracion
A41: Espera para recargar el boost | B41: =Base!B41 -> 2 | C41: s | D41: =Base!B41 -> 2 | E41: =IF(D41=0,"",B41/D41-1) -> 0 | F41: Segundos sin usarlo antes de que empiece a recargarse. | G41: boost_espera
...

Sheet Abrasanubes
A1: Abrasanubes
A2: Dragón del jugador. «Valor» sigue a la Base hasta que escribas otro número (su variación, en naranja).
A4: Stat | B4: Valor | C4: Unidad | D4: Base | E4: Diferencia | F4: Descripción | G4: Clave
A5: Vida y defensa
A6: Puntos de vida | B6: =Base!B6 -> 100 | C6: puntos | D6: =Base!B6 -> 100 | E6: =IF(D6=0,"",B6/D6-1) -> 0 | F6: Vida máxima. Ya no se regenera: lo que pierdes no vuelve hasta la siguiente misión (o al reaparecer en el combate libre). | G6: vida
A7: Puntos de armadura | B7: =Base!B7 -> 50 | C7: puntos | D7: =Base!B7 -> 50 | E7: =IF(D7=0,"",B7/D7-1) -> 0 | F7: Barra amarilla encima de la de vida. El daño la gasta primero a ella y, cuando llega a 0, a la vida. | G7: armadura
A8: Espera para regenerar la armadura | B8: =Base!B8 -> 5 | C8: s | D8: =Base!B8 -> 5 | E8: =IF(D8=0,"",B8/D8-1) -> 0 | F8: Segundos sin recibir daño antes de que la armadura empiece a rellenarse. | G8: armadura_espera
A9: Regeneración de armadura | B9: =Base!B9 -> 5 | C9: puntos/s | D9: =Base!B9 -> 5 | E9: =IF(D9=0,"",B9/D9-1) -> 0 | F9: Lo que se rellena cada segundo, hasta el máximo. | G9: armadura_regen
A10: Slots de escudo | B10: =Base!B10 -> 2 | C10: cargas | D10: =Base!B10 -> 2 | E10: =IF(D10=0,"",B10/D10-1) -> 0 | F10: Cargas del escudo (R) al empezar; también es el máximo. | G10: escudos
A11: Duración del escudo | B11: =Base!B11 -> 5 | C11: s | D11: =Base!B11 -> 5 | E11: =IF(D11=0,"",B11/D11-1) -> 0 | F11: Segundos que dura cada carga. | G11: escudo_duracion
A12: Escudo por dragón derribado | B12: =Base!B12 -> 1 | C12: cargas | D12: =Base!B12 -> 1 | E12: =IF(D12=0,"",B12/D12-1) -> 0 | F12: Cargas que devuelve cada dragón que derribas tú (0 = no se recargan). | G12: escudo_por_derribo
A13: Disparo básico (clic izquierdo)
A14: Daño disparo básico | B14: =Base!B14 -> 5 | C14: puntos | D14: =Base!B14 -> 5 | E14: =IF(D14=0,"",B14/D14-1) -> 0 | F14: Daño de cada impacto. | G14: basico_dano
A15: Munición disparo básico | B15: =Base!B15 -> 20 | C15: disparos | D15: =Base!B15 -> 20 | E15: =IF(D15=0,"",B15/D15-1) -> 0 | F15: Disparos seguidos; se recargan solos. | G15: basico_municion
A16: Pausa mínima entre disparos | B16: =Base!B16 -> 0.1 | C16: s | D16: =Base!B16 -> 0.1 | E16: =IF(D16=0,"",B16/D16-1) -> 0 | F16: Un disparo por clic, como mucho uno cada tanto. | G16: basico_pausa
A17: Espera antes de recargar | B17: =Base!B17 -> 1 | C17: s | D17: =Base!B17 -> 1 | E17: =IF(D17=0,"",B17/D17-1) -> 0 | F17: Segundos sin disparar antes de que vuelva la munición. | G17: basico_recarga_espera
A18: Recarga de munición | B18: =Base!B18 -> 8 | C18: disparos/s | D18: =Base!B18 -> 8 | E18: =IF(D18=0,"",B18/D18-1) -> 0 | F18: Disparos que vuelven cada segundo. | G18: basico_recarga
A19: Disparo guiado (clic izquierdo mantenido)
A20: Daño disparo guiado | B20: =Base!B20 -> 60 | C20: puntos | D20: =Base!B20 -> 60 | E20: =IF(D20=0,"",B20/D20-1) -> 0 | F20: Daño del impacto. | G20: guiado_dano
A21: Munición disparo guiado | B21: =Base!B21 -> 20 | C21: disparos | D21: =Base!B21 -> 20 | E21: =IF(D21=0,"",B21/D21-1) -> 0 | F21: Cantidad fija por misión: no se recargan. A 0, no hay más. | G21: guiado_municion
A22: Alcance del fijado | B22: =Base!B22 -> 3000 | C22: m | D22: =Base!B22 -> 3000 | E22: =IF(D22=0,"",B22/D22-1) -> 0 | F22: Distancia máxima al blanco para cargar el guiado. | G22: guiado_alcance
A23: Tiempo de fijado | B23: =Base!B23 -> 2 | C23: s | D23: =Base!B23 -> 2 | E23: =IF(D23=0,"",B23/D23-1) -> 0 | F23: Segundos con la mira en el círculo rojo hasta que sale (v31: 2, antes 3). | G23: guiado_fijado
A24: Lanzallamas (clic derecho)
A25: Daño lanzallamas | B25: =Base!B25 -> 15 | C25: puntos/s | D25: =Base!B25 -> 15 | E25: =IF(D25=0,"",B25/D25-1) -> 0 | F25: Daño por segundo a todo lo que toca. | G25: llamas_dano
A26: Alcance lanzallamas | B26: =Base!B26 -> 300 | C26: m | D26: =Base!B26 -> 300 | E26: =IF(D26=0,"",B26/D26-1) -> 0 | F26: Largo del chorro. | G26: llamas_alcance
A27: Tiempo sobrecarga del lanzallamas | B27: =Base!B27 -> 5 | C27: s | D27: =Base!B27 -> 5 | E27: =IF(D27=0,"",B27/D27-1) -> 0 | F27: Segundos de fuego seguido hasta sobrecalentarse. | G27: llamas_sobrecarga
A28: Tiempo sin armas al sobrecalentarse | B28: =Base!B28 -> 10 | C28: s | D28: =Base!B28 -> 10 | E28: =IF(D28=0,"",B28/D28-1) -> 0 | F28: Al sobrecalentarse, ninguna arma funciona durante este tiempo. | G28: llamas_bloqueo
A29: Tiempo en enfriarse | B29: =Base!B29 -> 4 | C29: s | D29: =Base!B29 -> 4 | E29: =IF(D29=0,"",B29/D29-1) -> 0 | F29: Al soltar antes de sobrecalentarse, el calor baja de 100 % a 0 en este tiempo. | G29: llamas_enfriado
A30: Rayo láser (los dos clics a la vez)
A31: Daño rayo láser | B31: =Base!B31 -> 50 | C31: puntos/s | D31: =Base!B31 -> 50 | E31: =IF(D31=0,"",B31/D31-1) -> 0 | F31: Daño por segundo a todo lo que cruza. | G31: rayo_dano
A32: Duración rayo láser | B32: =Base!B32 -> 5 | C32: s | D32: =Base!B32 -> 5 | E32: =IF(D32=0,"",B32/D32-1) -> 0 | F32: Segundos desde que lo lanzas. | G32: rayo_duracion
A33: Distancia rayo láser | B33: =Base!B33 -> 8 | C33: km | D33: =Base!B33 -> 8 | E33: =IF(D33=0,"",B33/D33-1) -> 0 | F33: Largo máximo del rayo (se corta al chocar con el terreno o una isla). | G33: rayo_alcance
A34: Recarga rayo láser | B34: =Base!B34 -> 0.5 | C34: %/s | D34: =Base!B34 -> 0.5 | E34: =IF(D34=0,"",B34/D34-1) -> 0 | F34: Carga con el tiempo (con 0,5 %/s, de 0 a 100 % en 200 s). | G34: rayo_recarga
A35: Recarga por enemigo destruido | B35: =Base!B35 -> 5 | C35: % | D35: =Base!B35 -> 5 | E35: =IF(D35=0,"",B35/D35-1) -> 0 | F35: Por cada dragón, torre, dirigible u otra unidad enemiga que destruyes tú (no Lance; los soldados sueltos no cuentan, el batallón entero sí). | G35: rayo_por_derribo
A36: Vuelo
A37: Velocidad máxima | B37: =Base!B37 -> 600 | C37: km/h | D37: =Base!B37 -> 600 | E37: =IF(D37=0,"",B37/D37-1) -> 0 | F37: A todo gas y en vuelo nivelado, sin boost (en picado se puede pasar). | G37: vel_max
A38: Velocidad boost | B38: =Base!B38 -> 1000 | C38: km/h | D38: =Base!B38 -> 1000 | E38: =IF(D38=0,"",B38/D38-1) -> 0 | F38: Con boost. También es el tope absoluto, picados incluidos. | G38: vel_boost
A39: Duración boost | B39: =Base!B39 -> 10 | C39: s | D39: =Base!B39 -> 10 | E39: =IF(D39=0,"",B39/D39-1) -> 0 | F39: Segundos de boost seguido con la barra llena. | G39: boost_duracion
A40: Aceleración del boost | B40: =Base!B40 -> 3 | C40: s | D40: =Base!B40 -> 3 | E40: =IF(D40=0,"",B40/D40-1) -> 0 | F40: Segundos en pasar de la velocidad máxima a la de boost. | G40: boost_aceleracion
A41: Espera para recargar el boost | B41: =Base!B41 -> 2 | C41: s | D41: =Base!B41 -> 2 | E41: =IF(D41=0,"",B41/D41-1) -> 0 | F41: Segundos sin usarlo antes de que empiece a recargarse. | G41: boost_espera
...

Sheet Ventoscuro
A1: Ventoscuro
A2: Dragón del jugador. «Valor» sigue a la Base hasta que escribas otro número (su variación, en naranja).
A4: Stat | B4: Valor | C4: Unidad | D4: Base | E4: Diferencia | F4: Descripción | G4: Clave
A5: Vida y defensa
A6: Puntos de vida | B6: =Base!B6 -> 100 | C6: puntos | D6: =Base!B6 -> 100 | E6: =IF(D6=0,"",B6/D6-1) -> 0 | F6: Vida máxima. Ya no se regenera: lo que pierdes no vuelve hasta la siguiente misión (o al reaparecer en el combate libre). | G6: vida
A7: Puntos de armadura | B7: =Base!B7 -> 50 | C7: puntos | D7: =Base!B7 -> 50 | E7: =IF(D7=0,"",B7/D7-1) -> 0 | F7: Barra amarilla encima de la de vida. El daño la gasta primero a ella y, cuando llega a 0, a la vida. | G7: armadura
A8: Espera para regenerar la armadura | B8: =Base!B8 -> 5 | C8: s | D8: =Base!B8 -> 5 | E8: =IF(D8=0,"",B8/D8-1) -> 0 | F8: Segundos sin recibir daño antes de que la armadura empiece a rellenarse. | G8: armadura_espera
A9: Regeneración de armadura | B9: =Base!B9 -> 5 | C9: puntos/s | D9: =Base!B9 -> 5 | E9: =IF(D9=0,"",B9/D9-1) -> 0 | F9: Lo que se rellena cada segundo, hasta el máximo. | G9: armadura_regen
A10: Slots de escudo | B10: =Base!B10 -> 2 | C10: cargas | D10: =Base!B10 -> 2 | E10: =IF(D10=0,"",B10/D10-1) -> 0 | F10: Cargas del escudo (R) al empezar; también es el máximo. | G10: escudos
A11: Duración del escudo | B11: =Base!B11 -> 5 | C11: s | D11: =Base!B11 -> 5 | E11: =IF(D11=0,"",B11/D11-1) -> 0 | F11: Segundos que dura cada carga. | G11: escudo_duracion
A12: Escudo por dragón derribado | B12: =Base!B12 -> 1 | C12: cargas | D12: =Base!B12 -> 1 | E12: =IF(D12=0,"",B12/D12-1) -> 0 | F12: Cargas que devuelve cada dragón que derribas tú (0 = no se recargan). | G12: escudo_por_derribo
A13: Disparo básico (clic izquierdo)
A14: Daño disparo básico | B14: =Base!B14 -> 5 | C14: puntos | D14: =Base!B14 -> 5 | E14: =IF(D14=0,"",B14/D14-1) -> 0 | F14: Daño de cada impacto. | G14: basico_dano
A15: Munición disparo básico | B15: =Base!B15 -> 20 | C15: disparos | D15: =Base!B15 -> 20 | E15: =IF(D15=0,"",B15/D15-1) -> 0 | F15: Disparos seguidos; se recargan solos. | G15: basico_municion
A16: Pausa mínima entre disparos | B16: =Base!B16 -> 0.1 | C16: s | D16: =Base!B16 -> 0.1 | E16: =IF(D16=0,"",B16/D16-1) -> 0 | F16: Un disparo por clic, como mucho uno cada tanto. | G16: basico_pausa
A17: Espera antes de recargar | B17: =Base!B17 -> 1 | C17: s | D17: =Base!B17 -> 1 | E17: =IF(D17=0,"",B17/D17-1) -> 0 | F17: Segundos sin disparar antes de que vuelva la munición. | G17: basico_recarga_espera
A18: Recarga de munición | B18: =Base!B18 -> 8 | C18: disparos/s | D18: =Base!B18 -> 8 | E18: =IF(D18=0,"",B18/D18-1) -> 0 | F18: Disparos que vuelven cada segundo. | G18: basico_recarga
A19: Disparo guiado (clic izquierdo mantenido)
A20: Daño disparo guiado | B20: =Base!B20 -> 60 | C20: puntos | D20: =Base!B20 -> 60 | E20: =IF(D20=0,"",B20/D20-1) -> 0 | F20: Daño del impacto. | G20: guiado_dano
A21: Munición disparo guiado | B21: =Base!B21 -> 20 | C21: disparos | D21: =Base!B21 -> 20 | E21: =IF(D21=0,"",B21/D21-1) -> 0 | F21: Cantidad fija por misión: no se recargan. A 0, no hay más. | G21: guiado_municion
A22: Alcance del fijado | B22: =Base!B22 -> 3000 | C22: m | D22: =Base!B22 -> 3000 | E22: =IF(D22=0,"",B22/D22-1) -> 0 | F22: Distancia máxima al blanco para cargar el guiado. | G22: guiado_alcance
A23: Tiempo de fijado | B23: =Base!B23 -> 2 | C23: s | D23: =Base!B23 -> 2 | E23: =IF(D23=0,"",B23/D23-1) -> 0 | F23: Segundos con la mira en el círculo rojo hasta que sale (v31: 2, antes 3). | G23: guiado_fijado
A24: Lanzallamas (clic derecho)
A25: Daño lanzallamas | B25: =Base!B25 -> 15 | C25: puntos/s | D25: =Base!B25 -> 15 | E25: =IF(D25=0,"",B25/D25-1) -> 0 | F25: Daño por segundo a todo lo que toca. | G25: llamas_dano
A26: Alcance lanzallamas | B26: =Base!B26 -> 300 | C26: m | D26: =Base!B26 -> 300 | E26: =IF(D26=0,"",B26/D26-1) -> 0 | F26: Largo del chorro. | G26: llamas_alcance
A27: Tiempo sobrecarga del lanzallamas | B27: =Base!B27 -> 5 | C27: s | D27: =Base!B27 -> 5 | E27: =IF(D27=0,"",B27/D27-1) -> 0 | F27: Segundos de fuego seguido hasta sobrecalentarse. | G27: llamas_sobrecarga
A28: Tiempo sin armas al sobrecalentarse | B28: =Base!B28 -> 10 | C28: s | D28: =Base!B28 -> 10 | E28: =IF(D28=0,"",B28/D28-1) -> 0 | F28: Al sobrecalentarse, ninguna arma funciona durante este tiempo. | G28: llamas_bloqueo
A29: Tiempo en enfriarse | B29: =Base!B29 -> 4 | C29: s | D29: =Base!B29 -> 4 | E29: =IF(D29=0,"",B29/D29-1) -> 0 | F29: Al soltar antes de sobrecalentarse, el calor baja de 100 % a 0 en este tiempo. | G29: llamas_enfriado
A30: Rayo láser (los dos clics a la vez)
A31: Daño rayo láser | B31: =Base!B31 -> 50 | C31: puntos/s | D31: =Base!B31 -> 50 | E31: =IF(D31=0,"",B31/D31-1) -> 0 | F31: Daño por segundo a todo lo que cruza. | G31: rayo_dano
A32: Duración rayo láser | B32: =Base!B32 -> 5 | C32: s | D32: =Base!B32 -> 5 | E32: =IF(D32=0,"",B32/D32-1) -> 0 | F32: Segundos desde que lo lanzas. | G32: rayo_duracion
A33: Distancia rayo láser | B33: =Base!B33 -> 8 | C33: km | D33: =Base!B33 -> 8 | E33: =IF(D33=0,"",B33/D33-1) -> 0 | F33: Largo máximo del rayo (se corta al chocar con el terreno o una isla). | G33: rayo_alcance
A34: Recarga rayo láser | B34: =Base!B34 -> 0.5 | C34: %/s | D34: =Base!B34 -> 0.5 | E34: =IF(D34=0,"",B34/D34-1) -> 0 | F34: Carga con el tiempo (con 0,5 %/s, de 0 a 100 % en 200 s). | G34: rayo_recarga
A35: Recarga por enemigo destruido | B35: =Base!B35 -> 5 | C35: % | D35: =Base!B35 -> 5 | E35: =IF(D35=0,"",B35/D35-1) -> 0 | F35: Por cada dragón, torre, dirigible u otra unidad enemiga que destruyes tú (no Lance; los soldados sueltos no cuentan, el batallón entero sí). | G35: rayo_por_derribo
A36: Vuelo
A37: Velocidad máxima | B37: =Base!B37 -> 600 | C37: km/h | D37: =Base!B37 -> 600 | E37: =IF(D37=0,"",B37/D37-1) -> 0 | F37: A todo gas y en vuelo nivelado, sin boost (en picado se puede pasar). | G37: vel_max
A38: Velocidad boost | B38: =Base!B38 -> 1000 | C38: km/h | D38: =Base!B38 -> 1000 | E38: =IF(D38=0,"",B38/D38-1) -> 0 | F38: Con boost. También es el tope absoluto, picados incluidos. | G38: vel_boost
A39: Duración boost | B39: =Base!B39 -> 10 | C39: s | D39: =Base!B39 -> 10 | E39: =IF(D39=0,"",B39/D39-1) -> 0 | F39: Segundos de boost seguido con la barra llena. | G39: boost_duracion
A40: Aceleración del boost | B40: =Base!B40 -> 3 | C40: s | D40: =Base!B40 -> 3 | E40: =IF(D40=0,"",B40/D40-1) -> 0 | F40: Segundos en pasar de la velocidad máxima a la de boost. | G40: boost_aceleracion
A41: Espera para recargar el boost | B41: =Base!B41 -> 2 | C41: s | D41: =Base!B41 -> 2 | E41: =IF(D41=0,"",B41/D41-1) -> 0 | F41: Segundos sin usarlo antes de que empiece a recargarse. | G41: boost_espera
...

Sheet Fulgor
A1: Fulgor
A2: Dragón del jugador. «Valor» sigue a la Base hasta que escribas otro número (su variación, en naranja).
A4: Stat | B4: Valor | C4: Unidad | D4: Base | E4: Diferencia | F4: Descripción | G4: Clave
A5: Vida y defensa
A6: Puntos de vida | B6: =Base!B6 -> 100 | C6: puntos | D6: =Base!B6 -> 100 | E6: =IF(D6=0,"",B6/D6-1) -> 0 | F6: Vida máxima. Ya no se regenera: lo que pierdes no vuelve hasta la siguiente misión (o al reaparecer en el combate libre). | G6: vida
A7: Puntos de armadura | B7: =Base!B7 -> 50 | C7: puntos | D7: =Base!B7 -> 50 | E7: =IF(D7=0,"",B7/D7-1) -> 0 | F7: Barra amarilla encima de la de vida. El daño la gasta primero a ella y, cuando llega a 0, a la vida. | G7: armadura
A8: Espera para regenerar la armadura | B8: =Base!B8 -> 5 | C8: s | D8: =Base!B8 -> 5 | E8: =IF(D8=0,"",B8/D8-1) -> 0 | F8: Segundos sin recibir daño antes de que la armadura empiece a rellenarse. | G8: armadura_espera
A9: Regeneración de armadura | B9: =Base!B9 -> 5 | C9: puntos/s | D9: =Base!B9 -> 5 | E9: =IF(D9=0,"",B9/D9-1) -> 0 | F9: Lo que se rellena cada segundo, hasta el máximo. | G9: armadura_regen
A10: Slots de escudo | B10: =Base!B10 -> 2 | C10: cargas | D10: =Base!B10 -> 2 | E10: =IF(D10=0,"",B10/D10-1) -> 0 | F10: Cargas del escudo (R) al empezar; también es el máximo. | G10: escudos
A11: Duración del escudo | B11: =Base!B11 -> 5 | C11: s | D11: =Base!B11 -> 5 | E11: =IF(D11=0,"",B11/D11-1) -> 0 | F11: Segundos que dura cada carga. | G11: escudo_duracion
A12: Escudo por dragón derribado | B12: =Base!B12 -> 1 | C12: cargas | D12: =Base!B12 -> 1 | E12: =IF(D12=0,"",B12/D12-1) -> 0 | F12: Cargas que devuelve cada dragón que derribas tú (0 = no se recargan). | G12: escudo_por_derribo
A13: Disparo básico (clic izquierdo)
A14: Daño disparo básico | B14: =Base!B14 -> 5 | C14: puntos | D14: =Base!B14 -> 5 | E14: =IF(D14=0,"",B14/D14-1) -> 0 | F14: Daño de cada impacto. | G14: basico_dano
A15: Munición disparo básico | B15: =Base!B15 -> 20 | C15: disparos | D15: =Base!B15 -> 20 | E15: =IF(D15=0,"",B15/D15-1) -> 0 | F15: Disparos seguidos; se recargan solos. | G15: basico_municion
A16: Pausa mínima entre disparos | B16: =Base!B16 -> 0.1 | C16: s | D16: =Base!B16 -> 0.1 | E16: =IF(D16=0,"",B16/D16-1) -> 0 | F16: Un disparo por clic, como mucho uno cada tanto. | G16: basico_pausa
A17: Espera antes de recargar | B17: =Base!B17 -> 1 | C17: s | D17: =Base!B17 -> 1 | E17: =IF(D17=0,"",B17/D17-1) -> 0 | F17: Segundos sin disparar antes de que vuelva la munición. | G17: basico_recarga_espera
A18: Recarga de munición | B18: =Base!B18 -> 8 | C18: disparos/s | D18: =Base!B18 -> 8 | E18: =IF(D18=0,"",B18/D18-1) -> 0 | F18: Disparos que vuelven cada segundo. | G18: basico_recarga
A19: Disparo guiado (clic izquierdo mantenido)
A20: Daño disparo guiado | B20: =Base!B20 -> 60 | C20: puntos | D20: =Base!B20 -> 60 | E20: =IF(D20=0,"",B20/D20-1) -> 0 | F20: Daño del impacto. | G20: guiado_dano
A21: Munición disparo guiado | B21: =Base!B21 -> 20 | C21: disparos | D21: =Base!B21 -> 20 | E21: =IF(D21=0,"",B21/D21-1) -> 0 | F21: Cantidad fija por misión: no se recargan. A 0, no hay más. | G21: guiado_municion
A22: Alcance del fijado | B22: =Base!B22 -> 3000 | C22: m | D22: =Base!B22 -> 3000 | E22: =IF(D22=0,"",B22/D22-1) -> 0 | F22: Distancia máxima al blanco para cargar el guiado. | G22: guiado_alcance
A23: Tiempo de fijado | B23: =Base!B23 -> 2 | C23: s | D23: =Base!B23 -> 2 | E23: =IF(D23=0,"",B23/D23-1) -> 0 | F23: Segundos con la mira en el círculo rojo hasta que sale (v31: 2, antes 3). | G23: guiado_fijado
A24: Lanzallamas (clic derecho)
A25: Daño lanzallamas | B25: =Base!B25 -> 15 | C25: puntos/s | D25: =Base!B25 -> 15 | E25: =IF(D25=0,"",B25/D25-1) -> 0 | F25: Daño por segundo a todo lo que toca. | G25: llamas_dano
A26: Alcance lanzallamas | B26: =Base!B26 -> 300 | C26: m | D26: =Base!B26 -> 300 | E26: =IF(D26=0,"",B26/D26-1) -> 0 | F26: Largo del chorro. | G26: llamas_alcance
A27: Tiempo sobrecarga del lanzallamas | B27: =Base!B27 -> 5 | C27: s | D27: =Base!B27 -> 5 | E27: =IF(D27=0,"",B27/D27-1) -> 0 | F27: Segundos de fuego seguido hasta sobrecalentarse. | G27: llamas_sobrecarga
A28: Tiempo sin armas al sobrecalentarse | B28: =Base!B28 -> 10 | C28: s | D28: =Base!B28 -> 10 | E28: =IF(D28=0,"",B28/D28-1) -> 0 | F28: Al sobrecalentarse, ninguna arma funciona durante este tiempo. | G28: llamas_bloqueo
A29: Tiempo en enfriarse | B29: =Base!B29 -> 4 | C29: s | D29: =Base!B29 -> 4 | E29: =IF(D29=0,"",B29/D29-1) -> 0 | F29: Al soltar antes de sobrecalentarse, el calor baja de 100 % a 0 en este tiempo. | G29: llamas_enfriado
A30: Rayo láser (los dos clics a la vez)
A31: Daño rayo láser | B31: =Base!B31 -> 50 | C31: puntos/s | D31: =Base!B31 -> 50 | E31: =IF(D31=0,"",B31/D31-1) -> 0 | F31: Daño por segundo a todo lo que cruza. | G31: rayo_dano
A32: Duración rayo láser | B32: =Base!B32 -> 5 | C32: s | D32: =Base!B32 -> 5 | E32: =IF(D32=0,"",B32/D32-1) -> 0 | F32: Segundos desde que lo lanzas. | G32: rayo_duracion
A33: Distancia rayo láser | B33: =Base!B33 -> 8 | C33: km | D33: =Base!B33 -> 8 | E33: =IF(D33=0,"",B33/D33-1) -> 0 | F33: Largo máximo del rayo (se corta al chocar con el terreno o una isla). | G33: rayo_alcance
A34: Recarga rayo láser | B34: =Base!B34 -> 0.5 | C34: %/s | D34: =Base!B34 -> 0.5 | E34: =IF(D34=0,"",B34/D34-1) -> 0 | F34: Carga con el tiempo (con 0,5 %/s, de 0 a 100 % en 200 s). | G34: rayo_recarga
A35: Recarga por enemigo destruido | B35: =Base!B35 -> 5 | C35: % | D35: =Base!B35 -> 5 | E35: =IF(D35=0,"",B35/D35-1) -> 0 | F35: Por cada dragón, torre, dirigible u otra unidad enemiga que destruyes tú (no Lance; los soldados sueltos no cuentan, el batallón entero sí). | G35: rayo_por_derribo
A36: Vuelo
A37: Velocidad máxima | B37: =Base!B37 -> 600 | C37: km/h | D37: =Base!B37 -> 600 | E37: =IF(D37=0,"",B37/D37-1) -> 0 | F37: A todo gas y en vuelo nivelado, sin boost (en picado se puede pasar). | G37: vel_max
A38: Velocidad boost | B38: =Base!B38 -> 1000 | C38: km/h | D38: =Base!B38 -> 1000 | E38: =IF(D38=0,"",B38/D38-1) -> 0 | F38: Con boost. También es el tope absoluto, picados incluidos. | G38: vel_boost
A39: Duración boost | B39: =Base!B39 -> 10 | C39: s | D39: =Base!B39 -> 10 | E39: =IF(D39=0,"",B39/D39-1) -> 0 | F39: Segundos de boost seguido con la barra llena. | G39: boost_duracion
A40: Aceleración del boost | B40: =Base!B40 -> 3 | C40: s | D40: =Base!B40 -> 3 | E40: =IF(D40=0,"",B40/D40-1) -> 0 | F40: Segundos en pasar de la velocidad máxima a la de boost. | G40: boost_aceleracion
A41: Espera para recargar el boost | B41: =Base!B41 -> 2 | C41: s | D41: =Base!B41 -> 2 | E41: =IF(D41=0,"",B41/D41-1) -> 0 | F41: Segundos sin usarlo antes de que empiece a recargarse. | G41: boost_espera
...

Sheet Dragón enemigo
A1: Dragón enemigo
A2: Valores de ahora, pendientes de rediseñar.
A4: Stat | B4: Valor | C4: Unidad | D4: Descripción | E4: Clave
A5: Vida y vuelo
A6: Puntos de vida | B6: 70 | C6: puntos | E6: vida
A7: Velocidad máxima | B7: 500 | C7: km/h | E7: velocidad
A8: Radio de giro | B8: 130 | C8: m | D8: El del giro más cerrado a su velocidad máxima: cuanto más grande, más abiertos sus giros. Si es mayor que el tuyo (Base: 110 m), al perseguirlo puedes cerrar el giro y apuntarle (v26: 130; antes, unos 104 m). | E8: giro_radio
A9: Distancia de detección | B9: 2000 | C9: m | D9: A esta distancia te detecta y empieza sus pasadas. | E9: deteccion
A10: Distancia a la que te pierde | B10: 3500 | C10: m | E10: perder
A11: Puntos al derribarlo | B11: 300 | C11: puntos | E11: puntos
A12: Huida (cuando le persigues)
A13: Distancia a la que se siente perseguido | B13: 1800 | C13: m | D13: Con el jugador detrás, apuntándole y más cerca que esto, huye hacia delante con maniobras amplias (eses, curvas abiertas, tirabuzón, subidas y picados). | E13: huida_distancia
A14: Tiempo de huida (mínimo) | B14: 10 | C14: s | D14: Pasado este tiempo (entre el mínimo y el máximo) da la vuelta con una curva abierta y vuelve a atacar. | E14: huida_min
A15: Tiempo de huida (máximo) | B15: 18 | C15: s | E15: huida_max
A16: Bola de fuego
A17: Daño bola de fuego | B17: 10 | C17: puntos | E17: bola_dano
A18: Alcance | B18: 1000 | C18: m | E18: bola_alcance
A19: Pausa entre bolas (mínima) | B19: 1.7 | C19: s | E19: bola_pausa_min
A20: Pausa entre bolas (máxima) | B20: 2.9 | C20: s | E20: bola_pausa_max
A21: Error de puntería | B21: 2.2 | C21: % de la distancia | E21: bola_error
A22: Bola guiada
A23: Daño bola guiada | B23: 30 | C23: puntos | E23: guiada_dano
A24: Tiempo de fijado | B24: 4 | C24: s | D24: Segundos fijándote (aviso «TE ESTÁN FIJANDO») antes de lanzarla. | E24: guiada_fijado
A25: Distancia mínima de lanzamiento | B25: 500 | C25: m | E25: guiada_alcance_min
A26: Distancia máxima de lanzamiento | B26: 2000 | C26: m | E26: guiada_alcance_max
A27: Pausa entre guiadas de un mismo dragón | B27: 60 | C27: s | E27: guiada_pausa
A28: Separación entre guiadas de todos | B28: 20 | C28: s | D28: Entre dos lanzamientos de dragones cualesquiera. | E28: guiada_separacion
A29: Velocidad máxima de la guiada | B29: 1152 | C29: km/h | E29: guiada_vel
A30: Giro de la guiada | B30: 30 | C30: °/s | D30: Cuanto menos, más fácil esquivarla rompiendo fuerte. | E30: guiada_giro
A31: Choques
A32: Daño que te hace al chocar | B32: 25 | C32: puntos | E32: choque_dano
A33: Daño que recibe al chocar | B33: 50 | C33: puntos | E33: choque_recibe

Sheet Torre
A1: Torre
A2: Valores de ahora, pendientes de rediseñar.
A4: Stat | B4: Valor | C4: Unidad | D4: Descripción | E4: Clave
A5: Vida
A6: Puntos de vida | B6: 60 | C6: puntos | E6: vida
A7: Puntos al destruirla | B7: 100 | C7: puntos | E7: puntos
A8: Un disparo guiado la destruye siempre | B8: 1 | C8: 1 = sí, 0 = no | D8: Con 1, una guiada la tira aunque haga menos daño que su vida. | E8: guiada_destruye
A9: Fuego antiaéreo
A10: Daño por proyectil | B10: 3 | C10: puntos | E10: aa_dano
A11: Alcance | B11: 1500 | C11: m | E11: aa_alcance
A12: Proyectiles por ráfaga | B12: 5 | C12: disparos | E12: aa_rafaga
A13: Pausa entre disparos de la ráfaga | B13: 0.12 | C13: s | E13: aa_cadencia
A14: Pausa entre ráfagas (mínima) | B14: 2.2 | C14: s | E14: aa_pausa_min
A15: Pausa entre ráfagas (máxima) | B15: 3.6 | C15: s | E15: aa_pausa_max
A16: Velocidad del proyectil | B16: 1100 | C16: m/s | E16: aa_vel
A17: Dispersión | B17: 2 | C17: ° | E17: aa_dispersion

Sheet Dirigible
A1: Dirigible
A2: Valores de ahora, pendientes de rediseñar.
A4: Stat | B4: Valor | C4: Unidad | D4: Descripción | E4: Clave
A5: Vida
A6: Puntos de vida | B6: 50 | C6: puntos | E6: vida
A7: Puntos al destruirlo | B7: 200 | C7: puntos | E7: puntos
A8: Cañones (solo por los costados)
A9: Daño por proyectil | B9: 1 | C9: puntos | E9: dano
A10: Alcance | B10: 2000 | C10: m | E10: alcance
A11: Pausa entre disparos | B11: 0.3 | C11: s | D11: Disparan sin pausas entre ráfagas. | E11: cadencia
A12: Velocidad del proyectil | B12: 800 | C12: m/s | E12: vel
A13: Dispersión | B13: 1.72 | C13: ° | E13: dispersion
A14: Ángulo muerto a proa y a popa | B14: 35 | C14: ° | D14: Medido desde el eje del barco: ahí no pueden apuntarte. | E14: muerto_proa
A15: Elevación máxima de los cañones | B15: 50 | C15: ° | D15: Más arriba o más abajo no pueden apuntarte. | E15: muerto_vertical

Sheet Artillería
A1: Artillería
A2: Nueva (v29): balistas, catapultas y cañones, la defensa terrestre móvil. Valores provisionales.
A4: Stat | B4: Valor | C4: Unidad | D4: Descripción | E4: Clave
A5: Vida
A6: Puntos de vida | B6: 40 | C6: puntos | D6: Balista, catapulta y cañón son iguales: solo cambia el aspecto (y el aspecto del proyectil). | E6: vida
A7: Puntos al destruirla | B7: 80 | C7: puntos | E7: puntos
A8: Tamaño y movimiento
A9: Largo | B9: 11 | C9: m | D9: Tamaño en el juego: los tres modelos se escalan a este largo. | E9: largo
A10: Velocidad | B10: 20 | C10: km/h | D10: Unidad de tierra lenta. Aún sin uso: en la galería están quietas (llegará con las misiones). | E10: velocidad
A11: Disparo (muy de vez en cuando)
A12: Daño por proyectil | B12: 3 | C12: puntos | D12: Anecdótico: en las misiones su papel será atacar a las unidades de tierra aliadas. | E12: dano
A13: Alcance | B13: 1500 | C13: m | E13: alcance
A14: Pausa entre disparos (mínima) | B14: 6 | C14: s | E14: pausa_min
A15: Pausa entre disparos (máxima) | B15: 10 | C15: s | E15: pausa_max
A16: Velocidad del proyectil | B16: 200 | C16: m/s | D16: Con parábola: la gravedad lo hace caer (apuntan con adelanto). | E16: vel
A17: Dispersión | B17: 2.5 | C17: ° | E17: dispersion

Sheet Batallón
A1: Batallón
A2: Nueva (v29): bloques de soldados, el objetivo de la llamarada a ras de tierra. Valores provisionales.
A4: Stat | B4: Valor | C4: Unidad | D4: Descripción | E4: Clave
A5: Soldados
A6: Soldados por batallón (mínimo) | B6: 80 | C6: soldados | D6: Cada bloque sale con un número al azar entre el mínimo y el máximo (la receta puede fijarlo). | E6: soldados_min
A7: Soldados por batallón (máximo) | B7: 300 | C7: soldados | E7: soldados_max
A8: Separación entre soldados | B8: 1.6 | C8: m | D8: En la formación rectangular. Se nota al empezar otra partida o al restaurar la galería. | E8: separacion
A9: Vida de cada soldado | B9: 2 | C9: puntos | D9: Con la llamarada (15/s) arden casi al instante. | E9: vida
A10: Puntos por soldado | B10: 2 | C10: puntos | E10: puntos_soldado
A11: Puntos al aniquilar el batallón | B11: 150 | C11: puntos | D11: Además de los de cada soldado. | E11: puntos
A12: Velocidad de marcha | B12: 5 | C12: km/h | D12: Aún sin uso: en la galería están quietos. | E12: velocidad
A13: Daño que reciben
A14: Radio extra de la llamarada | B14: 3 | C14: m | D14: Se suma al cono de la llamarada (2 m + un 11 % de la distancia). | E14: radio_llamas
A15: Radio del disparo básico | B15: 2.5 | C15: m | D15: Mueren los soldados a menos de esto del impacto. | E15: radio_basico
A16: Radio del disparo guiado | B16: 12 | C16: m | E16: radio_guiado
A17: Radio del rayo láser | B17: 5 | C17: m | E17: radio_rayo
A18: Flechas (sobre todo un efecto)
A19: Alcance | B19: 400 | C19: m | D19: Disparan cuando pasas a menos de esto. | E19: flechas_alcance
A20: Flechas por andanada | B20: 40 | C20: flechas | D20: Con el batallón entero (con menos soldados, menos flechas). | E20: flechas_andanada
A21: Pausa entre andanadas | B21: 2.5 | C21: s | E21: flechas_pausa
A22: Velocidad de las flechas | B22: 75 | C22: m/s | D22: Con parábola. | E22: flechas_vel
A23: Dispersión | B23: 4 | C23: ° | E23: flechas_dispersion
A24: Daño por flecha | B24: 0.1 | C24: puntos | D24: Despreciable, a propósito (en hover justo encima, ~1 punto por segundo). | E24: flechas_dano

Sheet Barco naval
A1: Barco naval
A2: Nueva (v29): barcos en el mar, como los dirigibles. Valores provisionales.
A4: Stat | B4: Valor | C4: Unidad | D4: Descripción | E4: Clave
A5: Vida
A6: Puntos de vida | B6: 50 | C6: puntos | D6: Como los dirigibles: un disparo guiado (60) lo hunde. | E6: vida
A7: Puntos al hundirlo | B7: 200 | C7: puntos | E7: puntos
A8: Tamaño y movimiento
A9: Eslora | B9: 110 | C9: m | E9: largo
A10: Velocidad | B10: 30 | C10: km/h | D10: Aún sin uso: en la galería están quietos. | E10: velocidad
A11: Cañones (solo por los costados, como los dirigibles)
A12: Daño por proyectil | B12: 2 | C12: puntos | E12: dano
A13: Alcance | B13: 2000 | C13: m | E13: alcance
A14: Pausa entre disparos | B14: 0.3 | C14: s | E14: cadencia
A15: Velocidad del proyectil | B15: 800 | C15: m/s | E15: vel
A16: Dispersión | B16: 1.72 | C16: ° | E16: dispersion
A17: Ángulo muerto a proa y a popa | B17: 35 | C17: ° | D17: Medido desde el eje del barco: ahí no pueden apuntarte. | E17: muerto_proa
A18: Elevación máxima de los cañones | B18: 70 | C18: ° | E18: muerto_vertical

Sheet Superdirigible
A1: Superdirigible
A2: Nueva (v29): megaestructura del cielo con torretas que se destruyen aparte. Valores provisionales.
A4: Stat | B4: Valor | C4: Unidad | D4: Descripción | E4: Clave
A5: Núcleo (el casco)
A6: Puntos de vida del núcleo | B6: 1500 | C6: puntos | D6: Se puede dañar aunque queden torretas; al caer, caen todas. | E6: vida
A7: Puntos al destruirlo | B7: 2000 | C7: puntos | E7: puntos
A8: Eslora | B8: 1000 | C8: m | D8: Jorge: 500 m como mínimo (v29) y luego el doble (v30). Las torretas no cambian de tamaño: quedan más separadas. | E8: largo
A9: Altura mínima de vuelo | B9: 1500 | C9: m | D9: Sobre el suelo. La receta puede ponerlo más alto, nunca más bajo. | E9: altura_min
A10: Velocidad | B10: 60 | C10: km/h | D10: Aún sin uso: en la galería está quieto. | E10: velocidad
A11: Torretas (cañones y balistas sobre la cubierta)
A12: Torretas por costado | B12: 6 | C12: torretas | D12: Alternan cañón y balista; se fijan y se destruyen una a una (como mucho 6). | E12: torretas
A13: Vida de cada torreta | B13: 50 | C13: puntos | E13: torreta_vida
A14: Puntos por torreta | B14: 100 | C14: puntos | E14: torreta_puntos
A15: Tamaño de cada torreta | B15: 24 | C15: m | E15: torreta_largo
A16: Pausa entre disparos de cada torreta | B16: 1.5 | C16: s | D16: Cada torreta dispara por su cuenta, solo hacia su costado. | E16: torreta_cadencia
A17: Daño por proyectil | B17: 2 | C17: puntos | D17: Como los cañones de los dirigibles. | E17: dano
A18: Alcance | B18: 2000 | C18: m | E18: alcance
A19: Velocidad del proyectil | B19: 800 | C19: m/s | E19: vel
A20: Dispersión | B20: 1.72 | C20: ° | E20: dispersion
A21: Ángulo muerto a proa y a popa | B21: 35 | C21: ° | D21: Como los dirigibles: medido desde el eje del casco. | E21: muerto_proa
A22: Elevación máxima | B22: 70 | C22: ° | E22: muerto_vertical

Sheet Sierpe
A1: Sierpe
A2: Nueva (v29): dragón serpiente gigante (minijefe) con hechiceros que la escudan. Valores provisionales.
A4: Stat | B4: Valor | C4: Unidad | D4: Descripción | E4: Clave
A5: Vida y tamaño
A6: Puntos de vida | B6: 3000 | C6: puntos | D6: Solo recibe daño cuando cae su escudo. | E6: vida
A7: Puntos al abatirla | B7: 5000 | C7: puntos | E7: puntos
A8: Largo | B8: 500 | C8: m | E8: largo
A9: Vuelo
A10: Altura de vuelo | B10: 2000 | C10: m | D10: Sobre el suelo, si la receta no dice otra. | E10: altura
A11: Radio del círculo | B11: 3500 | C11: m | D11: En vuelo circular: su patrulla (en la galería, sobre todo el campo). | E11: radio_circulo
A12: Velocidad | B12: 150 | C12: km/h | D12: En vuelo circular. | E12: velocidad
A13: Llamarada (si te pones delante de la cabeza)
A14: Daño | B14: 40 | C14: puntos/s | E14: llamas_dano
A15: Alcance | B15: 900 | C15: m | E15: llamas_alcance
A16: Ángulo para empezarla | B16: 25 | C16: ° | D16: Te tiene que tener delante de la cabeza, a menos de este ángulo. | E16: llamas_angulo
A17: Duración | B17: 4 | C17: s | E17: llamas_duracion
A18: Pausa entre llamaradas | B18: 6 | C18: s | E18: llamas_pausa
A19: Bolas de fuego (como los dragones enemigos)
A20: Daño | B20: 15 | C20: puntos | E20: bola_dano
A21: Alcance | B21: 1500 | C21: m | E21: bola_alcance
A22: Pausa entre bolas (mínima) | B22: 1.2 | C22: s | E22: bola_pausa_min
A23: Pausa entre bolas (máxima) | B23: 2.4 | C23: s | E23: bola_pausa_max
A24: Hechiceros y escudo
A25: Hechiceros en el lomo | B25: 3 | C25: hechiceros | D25: Mientras quede alguno, el escudo la protege de todo daño (como mucho 3). | E25: hechiceros
A26: Vida de cada hechicero | B26: 60 | C26: puntos | E26: hechicero_vida
A27: Puntos por hechicero | B27: 300 | C27: puntos | E27: hechicero_puntos

Sheet Lance (aliado)
A1: Lance (aliado)
A2: Compañero de escuadrón con IA (Misión 1). Valores de ahora, pendientes de rediseñar.
A4: Stat | B4: Valor | C4: Unidad | D4: Descripción | E4: Clave
A5: Armas (solo disparo básico y lanzallamas)
A6: Daño disparo básico | B6: 5 | C6: puntos | E6: basico_dano
A7: Pausa entre disparos (mínima) | B7: 0.14 | C7: s | E7: basico_pausa_min
A8: Pausa entre disparos (máxima) | B8: 0.26 | C8: s | E8: basico_pausa_max
A9: Alcance de tiro | B9: 1000 | C9: m | E9: basico_alcance
A10: Error de puntería | B10: 1 | C10: % de la distancia | E10: basico_error
A11: Daño lanzallamas | B11: 70 | C11: puntos/s | D11: El de antes de la v24 (el tuyo baja a 15). | E11: llamas_dano
A12: Alcance lanzallamas | B12: 200 | C12: m | E12: llamas_alcance
A13: Vuelo y combate
A14: Velocidad máxima | B14: 1100 | C14: km/h | D14: Para alcanzarte en formación; en combate vuela como los dragones enemigos. | E14: vel_max
A15: Distancia para entrar en combate | B15: 2000 | C15: m | D15: Con un enemigo a menos de esto (de ti o de él), deja la formación y ataca. | E15: combate_distancia
A16: Distancia de protección | B16: 1000 | C16: m | D16: Dragones que van a por ti a menos de esto: los que Lance prefiere atacar. | E16: proteger_dist
A17: Probabilidad de protegerte | B17: 60 | C17: % | D17: Al cambiar de blanco, elige a uno de esos dragones con esta probabilidad. | E17: proteger_prob
A18: Distancia de protección urgente | B18: 600 | C18: m | D18: Un dragón que va a por ti a menos de esto: Lance va a por él al momento. | E18: proteger_urgente
A19: Tiempo con el mismo blanco (mínimo) | B19: 5 | C19: s | E19: blanco_min
A20: Tiempo con el mismo blanco (máximo) | B20: 10 | C20: s | E20: blanco_max
